Internal Server Error: /user/login/
Traceback (most recent call last):
  File "C:\Users\bayou\AppData\Local\Programs\Python\Python313\Lib\site-packages\django\db\backends\utils.py", line 89, in _execute
    return self.cursor.execute(sql, params)
           ~~~~~~~~~~~~~~~~~~~^^^^^^^^^^^^^
  File "C:\Users\bayou\AppData\Local\Programs\Python\Python313\Lib\site-packages\django\db\backends\sqlite3\base.py", line 328, in execute
    return super().execute(query, params)
           ~~~~~~~~~~~~~~~^^^^^^^^^^^^^^^
sqlite3.OperationalError: no such table: django_session

The above exception was the direct cause of the following exception:

Traceback (most recent call last):
  File "C:\Users\bayou\AppData\Local\Programs\Python\Python313\Lib\site-packages\django\core\handlers\exception.py", line 55, in inner
    response = get_response(request)
  File "C:\Users\bayou\AppData\Local\Programs\Python\Python313\Lib\site-packages\django\utils\deprecation.py", line 136, in __call__
    response = self.process_response(request, response)
  File "C:\Users\bayou\AppData\Local\Programs\Python\Python313\Lib\site-packages\django\contrib\sessions\middleware.py", line 59, in process_response
    request.session.save()
    ~~~~~~~~~~~~~~~~~~~~^^
  File "C:\Users\bayou\AppData\Local\Programs\Python\Python313\Lib\site-packages\django\contrib\sessions\backends\db.py", line 80, in save
    return self.create()
           ~~~~~~~~~~~^^
  File "C:\Users\bayou\AppData\Local\Programs\Python\Python313\Lib\site-packages\django\contrib\sessions\backends\db.py", line 50, in create
    self._session_key = self._get_new_session_key()
                        ~~~~~~~~~~~~~~~~~~~~~~~~~^^
  File "C:\Users\bayou\AppData\Local\Programs\Python\Python313\Lib\site-packages\django\contrib\sessions\backends\base.py", line 150, in _get_new_session_key
    if not self.exists(session_key):
           ~~~~~~~~~~~^^^^^^^^^^^^^
  File "C:\Users\bayou\AppData\Local\Programs\Python\Python313\Lib\site-packages\django\contrib\sessions\backends\db.py", line 46, in exists
    return self.model.objects.filter(session_key=session_key).exists()
           ~~~~~~~~~~~~~~~~~~~~~~~~~~~~~~~~~~~~~~~~~~~~~~~~~~~~~~~~~^^
  File "C:\Users\bayou\AppData\Local\Programs\Python\Python313\Lib\site-packages\django\db\models\query.py", line 1241, in exists
    return self.query.has_results(using=self.db)
           ~~~~~~~~~~~~~~~~~~~~~~^^^^^^^^^^^^^^^
  File "C:\Users\bayou\AppData\Local\Programs\Python\Python313\Lib\site-packages\django\db\models\sql\query.py", line 598, in has_results
    return compiler.has_results()
           ~~~~~~~~~~~~~~~~~~~~^^
  File "C:\Users\bayou\AppData\Local\Programs\Python\Python313\Lib\site-packages\django\db\models\sql\compiler.py", line 1530, in has_results
    return bool(self.execute_sql(SINGLE))
                ~~~~~~~~~~~~~~~~^^^^^^^^
  File "C:\Users\bayou\AppData\Local\Programs\Python\Python313\Lib\site-packages\django\db\models\sql\compiler.py", line 1562, in execute_sql
    cursor.execute(sql, params)
    ~~~~~~~~~~~~~~^^^^^^^^^^^^^
  File "C:\Users\bayou\AppData\Local\Programs\Python\Python313\Lib\site-packages\django\db\backends\utils.py", line 102, in execute
    return super().execute(sql, params)
           ~~~~~~~~~~~~~~~^^^^^^^^^^^^^
  File "C:\Users\bayou\AppData\Local\Programs\Python\Python313\Lib\site-packages\django\db\backends\utils.py", line 67, in execute
    return self._execute_with_wrappers(
           ~~~~~~~~~~~~~~~~~~~~~~~~~~~^
        sql, params, many=False, executor=self._execute
        ^^^^^^^^^^^^^^^^^^^^^^^^^^^^^^^^^^^^^^^^^^^^^^^
    )
    ^
  File "C:\Users\bayou\AppData\Local\Programs\Python\Python313\Lib\site-packages\django\db\backends\utils.py", line 80, in _execute_with_wrappers
    return executor(sql, params, many, context)
  File "C:\Users\bayou\AppData\Local\Programs\Python\Python313\Lib\site-packages\django\db\backends\utils.py", line 84, in _execute
    with self.db.wrap_database_errors:
         ^^^^^^^^^^^^^^^^^^^^^^^^^^^^
  File "C:\Users\bayou\AppData\Local\Programs\Python\Python313\Lib\site-packages\django\db\utils.py", line 91, in __exit__
    raise dj_exc_value.with_traceback(traceback) from exc_value
  File "C:\Users\bayou\AppData\Local\Programs\Python\Python313\Lib\site-packages\django\db\backends\utils.py", line 89, in _execute
    return self.cursor.execute(sql, params)
           ~~~~~~~~~~~~~~~~~~~^^^^^^^^^^^^^
  File "C:\Users\bayou\AppData\Local\Programs\Python\Python313\Lib\site-packages\django\db\backends\sqlite3\base.py", line 328, in execute
    return super().execute(query, params)
           ~~~~~~~~~~~~~~~^^^^^^^^^^^^^^^
django.db.utils.OperationalError: no such table: django_session
"POST /user/login/ HTTP/1.1" 500 148266
